Issue while building the feature

Traceback (most recent call last):
  File "src/unicon/eal/backend/pty_backend.py", line 496, in unicon.eal.backend.pty_backend.RawPtySpawn._read
OSError: [Errno 5] Input/output error

The above exception was the direct cause of the following exception:

Traceback (most recent call last):
  File "src/unicon/statemachine/statemachine.py", line 737, in unicon.statemachine.statemachine.StateMachine.go_to
  File "src/unicon/statemachine/statetransition.py", line 469, in unicon.statemachine.statetransition.AnyStateTransition.do_transitions
  File "src/unicon/eal/backend/pty_backend.py", line 340, in unicon.eal.backend.pty_backend.RawSpawn.expect
  File "src/unicon/eal/backend/pty_backend.py", line 133, in unicon.eal.backend.pty_backend.RawSpawn.read_update_buffer
  File "src/unicon/eal/backend/pty_backend.py", line 118, in unicon.eal.backend.pty_backend.RawSpawn.read
  File "src/unicon/eal/backend/pty_backend.py", line 499, in unicon.eal.backend.pty_backend.RawPtySpawn._read
unicon.core.errors.EOF: ('Unable to read. Connection closed or not available', OSError(5, 'Input/output error'))

The above exception was the direct cause of the following exception:

Traceback (most recent call last):
  File "src/unicon/bases/connection.py", line 773, in unicon.bases.connection.Connection.connect
  File "src/unicon/bases/routers/connection_provider.py", line 227, in unicon.bases.routers.connection_provider.BaseSingleRpConnectionProvider.connect
  File "src/unicon/bases/routers/connection_provider.py", line 253, in unicon.bases.routers.connection_provider.BaseSingleRpConnectionProvider.establish_connection
  File "src/unicon/statemachine/statemachine.py", line 740, in unicon.statemachine.statemachine.StateMachine.go_to
unicon.core.errors.StateMachineError: Failed while bringing device to "any" state

The above exception was the direct cause of the following exception:

Traceback (most recent call last):
  File "src/genie/cli/commands/learn.py", line 365, in genie.cli.commands.learn.LearnCommand._retrieve_ops
  File "/home/swt/.local/lib/python3.8/site-packages/genie/libs/ops/platform/ios/platform.py", line 134, in learn
    self.make(final_call=True)
  File "/home/swt/.local/lib/python3.8/site-packages/genie/ops/base/base.py", line 103, in make
    self.maker.make(*args, **kwargs)
  File "src/genie/ops/base/maker.py", line 315, in genie.ops.base.maker.Maker.make
  File "src/genie/ops/base/maker.py", line 427, in genie.ops.base.maker.Maker._call_parser
  File "src/genie/metaparser/_metaparser.py", line 308, in genie.metaparser._metaparser.MetaParser.parse
  File "/home/swt/.local/lib/python3.8/site-packages/genie/libs/parser/iosxe/show_platform.py", line 433, in cli
    out = self.device.execute(self.cli_command)
  File "src/unicon/bases/routers/services.py", line 267, in unicon.bases.routers.services.BaseService.__call__
  File "src/unicon/bases/routers/services.py", line 167, in unicon.bases.routers.services.BaseService.pre_service
  File "src/unicon/bases/connection.py", line 780, in unicon.bases.connection.Connection.connect
unicon.core.errors.ConnectionError: failed to connect to A1
Failed while bringing device to "any" state
